[2024-11-18T08:32:17.997+0000] {taskinstance.py:1979} INFO - Dependencies all met for dep_context=non-requeueable deps ti=<TaskInstance: covid19_get_data.get_covid19_report_today scheduled__2020-07-18T00:00:00+00:00 [queued]>
[2024-11-18T08:32:18.010+0000] {taskinstance.py:1979} INFO - Dependencies all met for dep_context=requeueable deps ti=<TaskInstance: covid19_get_data.get_covid19_report_today scheduled__2020-07-18T00:00:00+00:00 [queued]>
[2024-11-18T08:32:18.011+0000] {taskinstance.py:2193} INFO - Starting attempt 1 of 1
[2024-11-18T08:32:18.038+0000] {taskinstance.py:2217} INFO - Executing <Task(SimpleHttpOperator): get_covid19_report_today> on 2020-07-18 00:00:00+00:00
[2024-11-18T08:32:18.046+0000] {standard_task_runner.py:60} INFO - Started process 24240 to run task
[2024-11-18T08:32:18.060+0000] {standard_task_runner.py:87} INFO - Running: ['***', 'tasks', 'run', 'covid19_get_data', 'get_covid19_report_today', 'scheduled__2020-07-18T00:00:00+00:00', '--job-id', '7285', '--raw', '--subdir', 'DAGS_FOLDER/covid19_get_data.py', '--cfg-path', '/tmp/tmpi1ldl1ba']
[2024-11-18T08:32:18.062+0000] {standard_task_runner.py:88} INFO - Job 7285: Subtask get_covid19_report_today
[2024-11-18T08:32:18.151+0000] {task_command.py:423} INFO - Running <TaskInstance: covid19_get_data.get_covid19_report_today scheduled__2020-07-18T00:00:00+00:00 [running]> on host 3c704ad499e6
[2024-11-18T08:32:18.353+0000] {taskinstance.py:2513} INFO - Exporting env vars: AIRFLOW_CTX_DAG_OWNER='***' AIRFLOW_CTX_DAG_ID='covid19_get_data' AIRFLOW_CTX_TASK_ID='get_covid19_report_today' AIRFLOW_CTX_EXECUTION_DATE='2020-07-18T00:00:00+00:00' AIRFLOW_CTX_TRY_NUMBER='1' AIRFLOW_CTX_DAG_RUN_ID='scheduled__2020-07-18T00:00:00+00:00'
[2024-11-18T08:32:18.357+0000] {http.py:169} INFO - Calling HTTP method
[2024-11-18T08:32:18.370+0000] {base.py:83} INFO - Using connection ID 'https_covid19_api' for task execution.
[2024-11-18T08:32:18.387+0000] {base.py:83} INFO - Using connection ID 'https_covid19_api' for task execution.
[2024-11-18T08:32:18.399+0000] {taskinstance.py:2731} ERROR - Task failed with exception
Traceback (most recent call last):
  File "/home/airflow/.local/lib/python3.8/site-packages/requests/adapters.py", line 454, in send
    conn = self.get_connection(request.url, proxies)
  File "/home/airflow/.local/lib/python3.8/site-packages/requests/adapters.py", line 356, in get_connection
    conn = self.poolmanager.connection_from_url(url)
  File "/home/airflow/.local/lib/python3.8/site-packages/urllib3/poolmanager.py", line 298, in connection_from_url
    u = parse_url(url)
  File "/home/airflow/.local/lib/python3.8/site-packages/urllib3/util/url.py", line 397, in parse_url
    return six.raise_from(LocationParseError(source_url), None)
  File "<string>", line 3, in raise_from
urllib3.exceptions.LocationParseError: Failed to parse: : https://covid19.ddc.moph.go.th//api/Cases/today-cases-all

During handling of the above exception, another exception occurred:

Traceback (most recent call last):
  File "/home/airflow/.local/lib/python3.8/site-packages/airflow/models/taskinstance.py", line 444, in _execute_task
    result = _execute_callable(context=context, **execute_callable_kwargs)
  File "/home/airflow/.local/lib/python3.8/site-packages/airflow/models/taskinstance.py", line 414, in _execute_callable
    return execute_callable(context=context, **execute_callable_kwargs)
  File "/home/airflow/.local/lib/python3.8/site-packages/airflow/providers/http/operators/http.py", line 166, in execute
    return self.execute_sync(context=context)
  File "/home/airflow/.local/lib/python3.8/site-packages/airflow/providers/http/operators/http.py", line 170, in execute_sync
    response = self.hook.run(self.endpoint, self.data, self.headers, self.extra_options)
  File "/home/airflow/.local/lib/python3.8/site-packages/airflow/providers/http/hooks/http.py", line 187, in run
    return self.run_and_check(session, prepped_request, extra_options)
  File "/home/airflow/.local/lib/python3.8/site-packages/airflow/providers/http/hooks/http.py", line 235, in run_and_check
    response = session.send(prepped_request, **send_kwargs)
  File "/home/airflow/.local/lib/python3.8/site-packages/requests/sessions.py", line 703, in send
    r = adapter.send(request, **kwargs)
  File "/home/airflow/.local/lib/python3.8/site-packages/requests/adapters.py", line 456, in send
    raise InvalidURL(e, request=request)
requests.exceptions.InvalidURL: Failed to parse: : https://covid19.ddc.moph.go.th//api/Cases/today-cases-all
[2024-11-18T08:32:18.428+0000] {taskinstance.py:1149} INFO - Marking task as FAILED. dag_id=covid19_get_data, task_id=get_covid19_report_today, execution_date=20200718T000000, start_date=20241118T083217, end_date=20241118T083218
[2024-11-18T08:32:18.459+0000] {standard_task_runner.py:107} ERROR - Failed to execute job 7285 for task get_covid19_report_today (Failed to parse: : https://covid19.ddc.moph.go.th//api/Cases/today-cases-all; 24240)
[2024-11-18T08:32:18.483+0000] {local_task_job_runner.py:234} INFO - Task exited with return code 1
[2024-11-18T08:32:18.629+0000] {taskinstance.py:3312} INFO - 0 downstream tasks scheduled from follow-on schedule check
