[2024-11-19T06:49:15.330+0000] {taskinstance.py:1979} INFO - Dependencies all met for dep_context=non-requeueable deps ti=<TaskInstance: my_pipeline.data_quality_check manual__2024-11-19T06:49:09.120312+00:00 [queued]>
[2024-11-19T06:49:15.339+0000] {taskinstance.py:1979} INFO - Dependencies all met for dep_context=requeueable deps ti=<TaskInstance: my_pipeline.data_quality_check manual__2024-11-19T06:49:09.120312+00:00 [queued]>
[2024-11-19T06:49:15.339+0000] {taskinstance.py:2193} INFO - Starting attempt 1 of 1
[2024-11-19T06:49:15.351+0000] {taskinstance.py:2217} INFO - Executing <Task(BranchPythonOperator): data_quality_check> on 2024-11-19 06:49:09.120312+00:00
[2024-11-19T06:49:15.358+0000] {standard_task_runner.py:60} INFO - Started process 53996 to run task
[2024-11-19T06:49:15.361+0000] {standard_task_runner.py:87} INFO - Running: ['***', 'tasks', 'run', 'my_pipeline', 'data_quality_check', 'manual__2024-11-19T06:49:09.120312+00:00', '--job-id', '11702', '--raw', '--subdir', 'DAGS_FOLDER/my_pipeline.py', '--cfg-path', '/tmp/tmpjb2xwv3f']
[2024-11-19T06:49:15.367+0000] {standard_task_runner.py:88} INFO - Job 11702: Subtask data_quality_check
[2024-11-19T06:49:15.416+0000] {task_command.py:423} INFO - Running <TaskInstance: my_pipeline.data_quality_check manual__2024-11-19T06:49:09.120312+00:00 [running]> on host 3c704ad499e6
[2024-11-19T06:49:15.494+0000] {taskinstance.py:2513} INFO - Exporting env vars: AIRFLOW_CTX_DAG_OWNER='***' AIRFLOW_CTX_DAG_ID='my_pipeline' AIRFLOW_CTX_TASK_ID='data_quality_check' AIRFLOW_CTX_EXECUTION_DATE='2024-11-19T06:49:09.120312+00:00' AIRFLOW_CTX_TRY_NUMBER='1' AIRFLOW_CTX_DAG_RUN_ID='manual__2024-11-19T06:49:09.120312+00:00'
[2024-11-19T06:49:15.503+0000] {python.py:202} INFO - Done. Returned value was: check_na_value
[2024-11-19T06:49:15.503+0000] {branch.py:35} INFO - Branch into check_na_value
[2024-11-19T06:49:15.504+0000] {skipmixin.py:178} INFO - Following branch check_na_value
[2024-11-19T06:49:15.514+0000] {taskinstance.py:2731} ERROR - Task failed with exception
Traceback (most recent call last):
  File "/home/airflow/.local/lib/python3.8/site-packages/airflow/models/taskinstance.py", line 444, in _execute_task
    result = _execute_callable(context=context, **execute_callable_kwargs)
  File "/home/airflow/.local/lib/python3.8/site-packages/airflow/models/taskinstance.py", line 414, in _execute_callable
    return execute_callable(context=context, **execute_callable_kwargs)
  File "/home/airflow/.local/lib/python3.8/site-packages/airflow/operators/python.py", line 234, in execute
    return self.do_branch(context, super().execute(context))
  File "/home/airflow/.local/lib/python3.8/site-packages/airflow/operators/branch.py", line 36, in do_branch
    self.skip_all_except(context["ti"], branches_to_execute)
  File "/home/airflow/.local/lib/python3.8/site-packages/airflow/models/skipmixin.py", line 213, in skip_all_except
    raise AirflowException(
airflow.exceptions.AirflowException: 'branch_task_ids' must contain only valid task_ids. Invalid tasks found: {'check_na_value'}.
[2024-11-19T06:49:15.518+0000] {taskinstance.py:1149} INFO - Marking task as FAILED. dag_id=my_pipeline, task_id=data_quality_check, execution_date=20241119T064909, start_date=20241119T064915, end_date=20241119T064915
[2024-11-19T06:49:15.530+0000] {standard_task_runner.py:107} ERROR - Failed to execute job 11702 for task data_quality_check ('branch_task_ids' must contain only valid task_ids. Invalid tasks found: {'check_na_value'}.; 53996)
[2024-11-19T06:49:15.573+0000] {local_task_job_runner.py:234} INFO - Task exited with return code 1
[2024-11-19T06:49:15.604+0000] {taskinstance.py:3312} INFO - 0 downstream tasks scheduled from follow-on schedule check
