[2024-11-18T06:18:41.664+0000] {taskinstance.py:1979} INFO - Dependencies all met for dep_context=non-requeueable deps ti=<TaskInstance: azure_blob_ingestion_with_upload.download_blob manual__2024-11-18T06:18:40.220010+00:00 [queued]>
[2024-11-18T06:18:41.672+0000] {taskinstance.py:1979} INFO - Dependencies all met for dep_context=requeueable deps ti=<TaskInstance: azure_blob_ingestion_with_upload.download_blob manual__2024-11-18T06:18:40.220010+00:00 [queued]>
[2024-11-18T06:18:41.673+0000] {taskinstance.py:2193} INFO - Starting attempt 1 of 1
[2024-11-18T06:18:41.691+0000] {taskinstance.py:2217} INFO - Executing <Task(PythonOperator): download_blob> on 2024-11-18 06:18:40.220010+00:00
[2024-11-18T06:18:41.698+0000] {standard_task_runner.py:60} INFO - Started process 14121 to run task
[2024-11-18T06:18:41.703+0000] {standard_task_runner.py:87} INFO - Running: ['***', 'tasks', 'run', 'azure_blob_ingestion_with_upload', 'download_blob', 'manual__2024-11-18T06:18:40.220010+00:00', '--job-id', '3664', '--raw', '--subdir', 'DAGS_FOLDER/Access_AzureBlobStorage.py', '--cfg-path', '/tmp/tmp1povaniz']
[2024-11-18T06:18:41.704+0000] {standard_task_runner.py:88} INFO - Job 3664: Subtask download_blob
[2024-11-18T06:18:41.759+0000] {task_command.py:423} INFO - Running <TaskInstance: azure_blob_ingestion_with_upload.download_blob manual__2024-11-18T06:18:40.220010+00:00 [running]> on host 3c704ad499e6
[2024-11-18T06:18:41.847+0000] {taskinstance.py:2513} INFO - Exporting env vars: AIRFLOW_CTX_DAG_OWNER='***' AIRFLOW_CTX_DAG_ID='azure_blob_ingestion_with_upload' AIRFLOW_CTX_TASK_ID='download_blob' AIRFLOW_CTX_EXECUTION_DATE='2024-11-18T06:18:40.220010+00:00' AIRFLOW_CTX_TRY_NUMBER='1' AIRFLOW_CTX_DAG_RUN_ID='manual__2024-11-18T06:18:40.220010+00:00'
[2024-11-18T06:18:41.853+0000] {_universal.py:514} INFO - Request URL: 'https://***lab2024.blob.core.windows.net/ais-container/phawatmk/test_local.txt'
Request method: 'GET'
Request headers:
    'x-ms-range': 'REDACTED'
    'x-ms-version': 'REDACTED'
    'Accept': 'application/xml'
    'User-Agent': 'azsdk-python-storage-blob/12.19.1 Python/3.8.18 (Linux-6.5.0-1025-azure-x86_64-with-glibc2.34)'
    'x-ms-date': 'REDACTED'
    'x-ms-client-request-id': 'f5179d9a-a574-11ef-8edf-0242ac120004'
    'Authorization': 'REDACTED'
No body was attached to the request
[2024-11-18T06:18:41.933+0000] {_universal.py:550} INFO - Response status: 404
Response headers:
    'Content-Length': '215'
    'Content-Type': 'application/xml'
    'Server': 'Windows-Azure-Blob/1.0 Microsoft-HTTPAPI/2.0'
    'x-ms-request-id': 'c91d6aec-301e-0068-7a81-39b793000000'
    'x-ms-client-request-id': 'f5179d9a-a574-11ef-8edf-0242ac120004'
    'x-ms-version': 'REDACTED'
    'x-ms-error-code': 'BlobNotFound'
    'Date': 'Mon, 18 Nov 2024 06:18:41 GMT'
[2024-11-18T06:18:41.936+0000] {taskinstance.py:2731} ERROR - Task failed with exception
Traceback (most recent call last):
  File "/home/airflow/.local/lib/python3.8/site-packages/airflow/models/taskinstance.py", line 444, in _execute_task
    result = _execute_callable(context=context, **execute_callable_kwargs)
  File "/home/airflow/.local/lib/python3.8/site-packages/airflow/models/taskinstance.py", line 414, in _execute_callable
    return execute_callable(context=context, **execute_callable_kwargs)
  File "/home/airflow/.local/lib/python3.8/site-packages/airflow/operators/python.py", line 200, in execute
    return_value = self.execute_callable()
  File "/home/airflow/.local/lib/python3.8/site-packages/airflow/operators/python.py", line 217, in execute_callable
    return self.python_callable(*self.op_args, **self.op_kwargs)
  File "/opt/airflow/dags/Access_AzureBlobStorage.py", line 29, in download_blob
    download_data = blob_client.download_blob()
  File "/home/airflow/.local/lib/python3.8/site-packages/azure/core/tracing/decorator.py", line 78, in wrapper_use_tracer
    return func(*args, **kwargs)
  File "/home/airflow/.local/lib/python3.8/site-packages/azure/storage/blob/_blob_client.py", line 942, in download_blob
    return StorageStreamDownloader(**options)
  File "/home/airflow/.local/lib/python3.8/site-packages/azure/storage/blob/_download.py", line 367, in __init__
    self._response = self._initial_request()
  File "/home/airflow/.local/lib/python3.8/site-packages/azure/storage/blob/_download.py", line 463, in _initial_request
    process_storage_error(error)
  File "/home/airflow/.local/lib/python3.8/site-packages/azure/storage/blob/_shared/response_handlers.py", line 184, in process_storage_error
    exec("raise error from None")   # pylint: disable=exec-used # nosec
  File "<string>", line 1, in <module>
  File "/home/airflow/.local/lib/python3.8/site-packages/azure/storage/blob/_download.py", line 415, in _initial_request
    location_mode, response = self._clients.blob.download(
  File "/home/airflow/.local/lib/python3.8/site-packages/azure/core/tracing/decorator.py", line 78, in wrapper_use_tracer
    return func(*args, **kwargs)
  File "/home/airflow/.local/lib/python3.8/site-packages/azure/storage/blob/_generated/operations/_blob_operations.py", line 1611, in download
    map_error(status_code=response.status_code, response=response, error_map=error_map)
  File "/home/airflow/.local/lib/python3.8/site-packages/azure/core/exceptions.py", line 164, in map_error
    raise error
azure.core.exceptions.ResourceNotFoundError: The specified blob does not exist.
RequestId:c91d6aec-301e-0068-7a81-39b793000000
Time:2024-11-18T06:18:41.9419457Z
ErrorCode:BlobNotFound
Content: <?xml version="1.0" encoding="utf-8"?><Error><Code>BlobNotFound</Code><Message>The specified blob does not exist.
RequestId:c91d6aec-301e-0068-7a81-39b793000000
Time:2024-11-18T06:18:41.9419457Z</Message></Error>
[2024-11-18T06:18:41.948+0000] {taskinstance.py:1149} INFO - Marking task as FAILED. dag_id=azure_blob_ingestion_with_upload, task_id=download_blob, execution_date=20241118T061840, start_date=20241118T061841, end_date=20241118T061841
[2024-11-18T06:18:41.961+0000] {standard_task_runner.py:107} ERROR - Failed to execute job 3664 for task download_blob (The specified blob does not exist.
RequestId:c91d6aec-301e-0068-7a81-39b793000000
Time:2024-11-18T06:18:41.9419457Z
ErrorCode:BlobNotFound
Content: <?xml version="1.0" encoding="utf-8"?><Error><Code>BlobNotFound</Code><Message>The specified blob does not exist.
RequestId:c91d6aec-301e-0068-7a81-39b793000000
Time:2024-11-18T06:18:41.9419457Z</Message></Error>; 14121)
[2024-11-18T06:18:41.994+0000] {local_task_job_runner.py:234} INFO - Task exited with return code 1
[2024-11-18T06:18:42.021+0000] {taskinstance.py:3312} INFO - 0 downstream tasks scheduled from follow-on schedule check
