[2024-11-18T08:02:52.885+0000] {taskinstance.py:1979} INFO - Dependencies all met for dep_context=non-requeueable deps ti=<TaskInstance: aws_s3_example.download_file scheduled__2024-11-17T00:00:00+00:00 [queued]>
[2024-11-18T08:02:52.896+0000] {taskinstance.py:1979} INFO - Dependencies all met for dep_context=requeueable deps ti=<TaskInstance: aws_s3_example.download_file scheduled__2024-11-17T00:00:00+00:00 [queued]>
[2024-11-18T08:02:52.897+0000] {taskinstance.py:2193} INFO - Starting attempt 1 of 2
[2024-11-18T08:02:52.914+0000] {taskinstance.py:2217} INFO - Executing <Task(PythonOperator): download_file> on 2024-11-17 00:00:00+00:00
[2024-11-18T08:02:52.922+0000] {standard_task_runner.py:60} INFO - Started process 15751 to run task
[2024-11-18T08:02:52.927+0000] {standard_task_runner.py:87} INFO - Running: ['***', 'tasks', 'run', 'aws_s3_example', 'download_file', 'scheduled__2024-11-17T00:00:00+00:00', '--job-id', '3704', '--raw', '--subdir', 'DAGS_FOLDER/AWS_S3.py', '--cfg-path', '/tmp/tmpzq8gxs3u']
[2024-11-18T08:02:52.928+0000] {standard_task_runner.py:88} INFO - Job 3704: Subtask download_file
[2024-11-18T08:02:52.998+0000] {task_command.py:423} INFO - Running <TaskInstance: aws_s3_example.download_file scheduled__2024-11-17T00:00:00+00:00 [running]> on host 3c704ad499e6
[2024-11-18T08:02:53.089+0000] {taskinstance.py:2513} INFO - Exporting env vars: AIRFLOW_CTX_DAG_OWNER='***' AIRFLOW_CTX_DAG_ID='aws_s3_example' AIRFLOW_CTX_TASK_ID='download_file' AIRFLOW_CTX_EXECUTION_DATE='2024-11-17T00:00:00+00:00' AIRFLOW_CTX_TRY_NUMBER='1' AIRFLOW_CTX_DAG_RUN_ID='scheduled__2024-11-17T00:00:00+00:00'
[2024-11-18T08:02:53.100+0000] {base.py:83} INFO - Using connection ID 'aws_s3_conn' for task execution.
[2024-11-18T08:02:53.101+0000] {connection_wrapper.py:384} INFO - AWS Connection (conn_id='aws_s3_conn', conn_type='aws') credentials retrieved from login and password.
[2024-11-18T08:02:53.731+0000] {taskinstance.py:2731} ERROR - Task failed with exception
Traceback (most recent call last):
  File "/home/airflow/.local/lib/python3.8/site-packages/airflow/models/taskinstance.py", line 444, in _execute_task
    result = _execute_callable(context=context, **execute_callable_kwargs)
  File "/home/airflow/.local/lib/python3.8/site-packages/airflow/models/taskinstance.py", line 414, in _execute_callable
    return execute_callable(context=context, **execute_callable_kwargs)
  File "/home/airflow/.local/lib/python3.8/site-packages/airflow/operators/python.py", line 200, in execute
    return_value = self.execute_callable()
  File "/home/airflow/.local/lib/python3.8/site-packages/airflow/operators/python.py", line 217, in execute_callable
    return self.python_callable(*self.op_args, **self.op_kwargs)
  File "/opt/airflow/dags/AWS_S3.py", line 23, in download_file_from_s3
    with open(local_path, 'wb') as f:
PermissionError: [Errno 13] Permission denied: '/opt/airflow/dags/output/sample_data.txt'
[2024-11-18T08:02:53.739+0000] {taskinstance.py:1149} INFO - Marking task as UP_FOR_RETRY. dag_id=aws_s3_example, task_id=download_file, execution_date=20241117T000000, start_date=20241118T080252, end_date=20241118T080253
[2024-11-18T08:02:53.753+0000] {standard_task_runner.py:107} ERROR - Failed to execute job 3704 for task download_file ([Errno 13] Permission denied: '/opt/airflow/dags/output/sample_data.txt'; 15751)
[2024-11-18T08:02:53.781+0000] {local_task_job_runner.py:234} INFO - Task exited with return code 1
[2024-11-18T08:02:53.797+0000] {taskinstance.py:3312} INFO - 0 downstream tasks scheduled from follow-on schedule check
